Workbook
Name ArtistNames: MainLists!$A$2:$A$982
Name InstrumentNames: MainLists!$B$2:$B$982
Name RagaNames: MainLists!$C$2:$C$982
Name TonicNames: MainLists!$D$2:$D$13

Sheet Schema
A1: Column Name | B1: Description
A2: Raga | B2: Canonical name of the raga
A3: Name | B3: Name of video/Title of songs + link
A4: Instrument | B4: Main instrument (vocal being one)
A5: Artist name | B5: Artist full name
A6: Channel | B6: Name of channel on Youtube (TBD for other sources)
A7: Start time | B7: Start time of period of interest for analysis
A8: End time | B8: End time of period of interest for analysis

Sheet Database
A1: Raga | B1: Tonic | C1: File_name | D1: Link | E1: Instrument | F1: Artist | G1: Start time | H1: Gender | I1: Channel | J1: Bandish | K1: End time | L1: Notes
A2: Abhogi | B2: C# | C2: =A2&"_"&COUNTIF($A$2:A2,A2) -> Abhogi_1 | E2: Vocal | F2: Bhimsen Joshi | H2: =VLOOKUP(F2, ArtistCount!$A$1:$C$286, 3, FALSE) -> #N/A | I2: CompMusic DB
A3: Abhogi | B3: C# | C3: =A3&"_"&COUNTIF($A$2:A3,A3) -> Abhogi_2 | E3: Vocal | F3: Bhimsen Joshi | H3: =VLOOKUP(F3, ArtistCount!$A$1:$C$286, 3, FALSE) -> #N/A | I3: CompMusic DB
A4: Abhogi | B4: E | C4: =A4&"_"&COUNTIF($A$2:A4,A4) -> Abhogi_3 | E4: Vocal | F4: Bhimsen Joshi | H4: =VLOOKUP(F4, ArtistCount!$A$1:$C$286, 3, FALSE) -> #N/A | I4: CompMusic DB
A5: Abhogi | B5: A | C5: =A5&"_"&COUNTIF($A$2:A5,A5) -> Abhogi_4 | E5: Vocal | F5: Sanjeev Abhyankar | H5: =VLOOKUP(F5, ArtistCount!$A$1:$C$286, 3, FALSE) -> #N/A | I5: CompMusic DB
A6: Abhogi | B6: C# | C6: =A6&"_"&COUNTIF($A$2:A6,A6) -> Abhogi_5 | E6: Vocal | F6: Jagdish Prasad | H6: =VLOOKUP(F6, ArtistCount!$A$1:$C$286, 3, FALSE) -> #N/A | I6: CompMusic DB
A7: Abhogi | B7: D | C7: =A7&"_"&COUNTIF($A$2:A7,A7) -> Abhogi_6 | E7: Vocal | F7: Anol Chatterjee | H7: =VLOOKUP(F7, ArtistCount!$A$1:$C$286, 3, FALSE) -> #N/A | I7: CompMusic DB
A8: Abhogi | B8: D | C8: =A8&"_"&COUNTIF($A$2:A8,A8) -> Abhogi_7 | E8: Vocal | F8: Rashid Khan | H8: =VLOOKUP(F8, ArtistCount!$A$1:$C$286, 3, FALSE) -> #N/A | I8: CompMusic DB
A9: Abhogi | B9: C# | C9: =A9&"_"&COUNTIF($A$2:A9,A9) -> Abhogi_8 | E9: Vocal | F9: Salamat Ali Khan | H9: =VLOOKUP(F9, ArtistCount!$A$1:$C$286, 3, FALSE) -> #N/A | I9: CompMusic DB
A10: Abhogi | B10: C | C10: =A10&"_"&COUNTIF($A$2:A10,A10) -> Abhogi_9 | E10: Vocal | F10: Ajoy Chakraborti | H10: =VLOOKUP(F10, ArtistCount!$A$1:$C$286, 3, FALSE) -> #N/A | I10: CompMusic DB
A11: Abhogi | B11: A# | C11: =A11&"_"&COUNTIF($A$2:A11,A11) -> Abhogi_10 | E11: Vocal | F11: Girija Devi | H11: =VLOOKUP(F11, ArtistCount!$A$1:$C$286, 3, FALSE) -> #N/A | I11: CompMusic DB
A12: Adana | B12: C# | C12: =A12&"_"&COUNTIF($A$2:A12,A12) -> Adana_1 | D12: Raag Adana | Pt. Ajoy Chakraborty | Hindustani Classical Vocal | Part 5/7 | E12: Vocal | F12: Ajoy Chakraborti | H12: =VLOOKUP(F12, ArtistCount!$A$1:$C$286, 3, FALSE) -> #N/A | I12: Komal Nishad
A13: Adana | B13: D# | C13: =A13&"_"&COUNTIF($A$2:A13,A13) -> Adana_2 | D13: https://youtu.be/HyrXaj896jA?si=_z_Hbbdns67FtXyv | E13: Vocal | F13: Umrao Khan | H13: =VLOOKUP(F13, ArtistCount!$A$1:$C$286, 3, FALSE) -> #N/A | I13: The Dream Journey
A14: Adana | B14: D# | C14: =A14&"_"&COUNTIF($A$2:A14,A14) -> Adana_3 | D14: https://youtu.be/yQfyusksjt4?si=oksGRG3MlcBQgqYN | E14: Vocal | F14: Jayateerth Mevundi | H14: =VLOOKUP(F14, ArtistCount!$A$1:$C$286, 3, FALSE) -> #N/A | I14: Komal Nishad
A15: Adana | B15: C# | C15: =A15&"_"&COUNTIF($A$2:A15,A15) -> Adana_4 | D15: https://youtu.be/59fzA3Ipn-E?si=5onUBzyHCrs1EwOP | E15: Vocal | F15: Uday Bhawalkar | H15: =VLOOKUP(F15, ArtistCount!$A$1:$C$286, 3, FALSE) -> #N/A
A16: Adana | B16: D# | C16: =A16&"_"&COUNTIF($A$2:A16,A16) -> Adana_5 | D16: https://youtu.be/Oi_6zNupJvk?si=GLKimNqBgC6NqVaa | E16: Vocal | F16: Venkatesh Kumar | H16: =VLOOKUP(F16, ArtistCount!$A$1:$C$286, 3, FALSE) -> #N/A
A17: Adana | B17: C# | C17: =A17&"_"&COUNTIF($A$2:A17,A17) -> Adana_6 | D17: https://youtu.be/Hnw3BF08xSk?si=WKfZ_CIvRkC29Ij1 | E17: Vocal | F17: Ustad Salamat Ali & Ustad Nazakat Ali | H17: =VLOOKUP(F17, ArtistCount!$A$1:$C$286, 3, FALSE) -> #N/A
A18: Adana | B18: C | C18: =A18&"_"&COUNTIF($A$2:A18,A18) -> Adana_7 | D18: https://youtu.be/1dTwD7dDzL4?si=4OA4jayRi8GqH7kp | E18: Vocal | F18: Pt. Jasraj | H18: =VLOOKUP(F18, ArtistCount!$A$1:$C$286, 3, FALSE) -> #N/A
A19: Adana | B19: C# | C19: =A19&"_"&COUNTIF($A$2:A19,A19) -> Adana_8 | D19: https://youtu.be/7AYHKNG_qBo?si=BckiNEhrb8k-hRb3 | E19: Vocal | F19: Ajoy Chakraborti | H19: =VLOOKUP(F19, ArtistCount!$A$1:$C$286, 3, FALSE) -> #N/A
A20: Adana | B20: F | C20: =A20&"_"&COUNTIF($A$2:A20,A20) -> Adana_9 | D20: https://youtu.be/RmBivLu-8HQ?si=odS481-bF8FvzzWI | E20: Vocal | F20: Aniruddh Aithal | H20: =VLOOKUP(F20, ArtistCount!$A$1:$C$286, 3, FALSE) -> #N/A | L20: Recording is not great
A21: Adana | B21: B | C21: =A21&"_"&COUNTIF($A$2:A21,A21) -> Adana_10 | D21: https://www.youtube.com/watch?v=B4w6ZlhWVIs | E21: Vocal | F21: Veena Sahasrabuddhe | H21: =VLOOKUP(F21, ArtistCount!$A$1:$C$286, 3, FALSE) -> #N/A
A22: Ahir Bhairav | B22: F | C22: =A22&"_"&COUNTIF($A$2:A22,A22) -> Ahir Bhairav_1 | E22: Vocal | F22: Kaivalyakumar | H22: =VLOOKUP(F22, ArtistCount!$A$1:$C$286, 3, FALSE) -> #N/A | I22: CompMusic DB
A23: Ahir Bhairav | B23: F# | C23: =A23&"_"&COUNTIF($A$2:A23,A23) -> Ahir Bhairav_2 | E23: Vocal | F23: Kumar Gandharv | H23: =VLOOKUP(F23, ArtistCount!$A$1:$C$286, 3, FALSE) -> #N/A | I23: CompMusic DB
A24: Ahir Bhairav | B24: D | C24: =A24&"_"&COUNTIF($A$2:A24,A24) -> Ahir Bhairav_3 | E24: Vocal | F24: Amir Khan | H24: =VLOOKUP(F24, ArtistCount!$A$1:$C$286, 3, FALSE) -> #N/A | I24: CompMusic DB
A25: Ahir Bhairav | B25: C# | C25: =A25&"_"&COUNTIF($A$2:A25,A25) -> Ahir Bhairav_4 | E25: Vocal | F25: Pt. Jasraj | H25: =VLOOKUP(F25, ArtistCount!$A$1:$C$286, 3, FALSE) -> #N/A | I25: CompMusic DB
A26: Ahir Bhairav | B26: C# | C26: =A26&"_"&COUNTIF($A$2:A26,A26) -> Ahir Bhairav_5 | E26: Vocal | F26: Pt. Jasraj | H26: =VLOOKUP(F26, ArtistCount!$A$1:$C$286, 3, FALSE) -> #N/A | I26: CompMusic DB
A27: Ahir Bhairav | B27: D# | C27: =A27&"_"&COUNTIF($A$2:A27,A27) -> Ahir Bhairav_6 | E27: Vocal | F27: Rashid Khan | H27: =VLOOKUP(F27, ArtistCount!$A$1:$C$286, 3, FALSE) -> #N/A | I27: CompMusic DB
A28: Ahir Bhairav | B28: F# | C28: =A28&"_"&COUNTIF($A$2:A28,A28) -> Ahir Bhairav_7 | E28: Vocal | F28: Kumar Gandharv | H28: =VLOOKUP(F28, ArtistCount!$A$1:$C$286, 3, FALSE) -> #N/A | I28: CompMusic DB
A29: Ahir Bhairav | B29: D# | C29: =A29&"_"&COUNTIF($A$2:A29,A29) -> Ahir Bhairav_8 | E29: Vocal | F29: Omkar Dadarkar | H29: =VLOOKUP(F29, ArtistCount!$A$1:$C$286, 3, FALSE) -> #N/A | I29: CompMusic DB
A30: Ahir Bhairav | B30: A# | C30: =A30&"_"&COUNTIF($A$2:A30,A30) -> Ahir Bhairav_9 | E30: Vocal | F30: Hirabai Barodekar | H30: =VLOOKUP(F30, ArtistCount!$A$1:$C$286, 3, FALSE) -> #N/A | I30: CompMusic DB
A31: Ahir Bhairav | B31: C# | C31: =A31&"_"&COUNTIF($A$2:A31,A31) -> Ahir Bhairav_10 | E31: Vocal | F31: Ajoy Chakraborti | H31: =VLOOKUP(F31, ArtistCount!$A$1:$C$286, 3, FALSE) -> #N/A | I31: CompMusic DB
A32: Alhaiya Bilawal | B32: D | C32: =A32&"_"&COUNTIF($A$2:A32,A32) -> Alhaiya Bilawal_1 | E32: Vocal | F32: Dattatreya L Velankar | H32: =VLOOKUP(F32, ArtistCount!$A$1:$C$286, 3, FALSE) -> #N/A | I32: CompMusic DB
A33: Alhaiya Bilawal | B33: D | C33: =A33&"_"&COUNTIF($A$2:A33,A33) -> Alhaiya Bilawal_2 | E33: Vocal | F33: Dattatreya L Velankar | H33: =VLOOKUP(F33, ArtistCount!$A$1:$C$286, 3, FALSE) -> #N/A | I33: CompMusic DB
... A41: Alhaiya Bilawal | B41: C# | C41: =A41&"_"&COUNTIF($A$2:A41,A41) -> Alhaiya Bilawal_10 | E41: Vocal | F41: Aslam Khan | H41: =VLOOKUP(F41, ArtistCount!$A$1:$C$286, 3, FALSE) -> #N/A | I41: CompMusic DB
A42: Asavari (komal re) | B42: D# | C42: =A42&"_"&COUNTIF($A$2:A42,A42) -> Asavari (komal re)_1 | D42: https://youtu.be/QxuDG00m3-Y?si=0_Zgoy1s3GWoH2Ka | E42: Vocal | F42: Venkatesh Kumar | H42: =VLOOKUP(F42, ArtistCount!$A$1:$C$286, 3, FALSE) -> #N/A | I42: First Edition Arts
A43: Asavari (komal re) | B43: D# | C43: =A43&"_"&COUNTIF($A$2:A43,A43) -> Asavari (komal re)_2 | D43: https://youtu.be/4lHpL82SM3g?si=jLhiatiJWRHKXrSi | E43: Vocal | F43: Omkar Dadarkar | H43: =VLOOKUP(F43, ArtistCount!$A$1:$C$286, 3, FALSE) -> #N/A
A44: Asavari (komal re) | B44: D# | C44: =A44&"_"&COUNTIF($A$2:A44,A44) -> Asavari (komal re)_3 | D44: https://youtu.be/juftd3yg_wY?si=LrX1g7ur3pZOeox3 | E44: Vocal | F44: Ulhas Kashalkar | H44: =VLOOKUP(F44, ArtistCount!$A$1:$C$286, 3, FALSE) -> #N/A
A45: Asavari (komal re) | B45: E | C45: =A45&"_"&COUNTIF($A$2:A45,A45) -> Asavari (komal re)_4 | D45: https://youtu.be/s7WRnU0Fi0U?si=IC5cSqLJ9MFvF3zf | E45: Vocal | F45: Moinuddin and Nasir Aminuddin Dagar | H45: =VLOOKUP(F45, ArtistCount!$A$1:$C$286, 3, FALSE) -> #N/A | L45: Some note between D# and E but not either of them
A46: Asavari (komal re) | B46: C | C46: =A46&"_"&COUNTIF($A$2:A46,A46) -> Asavari (komal re)_5 | D46: https://youtu.be/Z-SUL_6JiKs?si=EGl5zWM__bU5C9Kn | E46: Vocal | F46: Amir Khan | H46: =VLOOKUP(F46, ArtistCount!$A$1:$C$286, 3, FALSE) -> #N/A
A47: Asavari (komal re) | B47: C# | C47: =A47&"_"&COUNTIF($A$2:A47,A47) -> Asavari (komal re)_6 | D47: https://youtu.be/lahaD7-B8DQ?si=-jxgx294FjSrNzjE | E47: Vocal | F47: Amir Khan | H47: =VLOOKUP(F47, ArtistCount!$A$1:$C$286, 3, FALSE) -> #N/A
...

Sheet Tonic vs Gender
A1: =IFERROR(__xludf.DUMMYFUNCTION("QUERY(Database!A:L, ""SELECT B, COUNT(B) WHERE F = 'Vocal' GROUP BY B PIVOT I"", 1)"),"Tonic") -> Tonic | B1: =IFERROR(__xludf.DUMMYFUNCTION("""COMPUTED_VALUE"""),"count Tonic") -> count Tonic

Sheet median pitch
A1: track_name | B1: vocals | C1: accompaniment | D1: Gender
A2: Abhogi_1 | B2: 175.435 | C2: 93.24 | D2: =Database!H2 -> #N/A
A3: Abhogi_2 | B3: 171.375 | C3: 93.26 | D3: =Database!H3 -> #N/A
A4: Abhogi_3 | B4: 185.33 | C4: 86.82 | D4: =Database!H4 -> #N/A
A5: Abhogi_4 | B5: 247.93 | C5: 106.7 | D5: =Database!H5 -> #N/A
A6: Abhogi_5 | B6: 159.13 | C6: 84.33 | D6: =Database!H6 -> #N/A
A7: Abhogi_6 | B7: 168.45 | C7: 147.14 | D7: =Database!H7 -> #N/A
A8: Abhogi_7 | B8: 174.92 | C8: 124.42 | D8: =Database!H8 -> #N/A
A9: Abhogi_8 | B9: 157.98 | C9: 137.35 | D9: =Database!H9 -> #N/A
A10: Abhogi_9 | B10: 147.37 | C10: 131.22 | D10: =Database!H10 -> #N/A
A11: Abhogi_10 | B11: 261.45 | C11: 156.05 | D11: =Database!H11 -> #N/A
A12: Adana_1 | B12: 253.34 | C12: 93.21 | D12: =Database!H12 -> #N/A
A13: Adana_2 | B13: 277.03 | C13: 156.06 | D13: =Database!H13 -> #N/A
... A164: Bhupali_6 | B164: 265.48 | C164: 99.95 | D164: =Database!H164 -> #N/A
A165: Bhupali_7 | B165: 173.92 | C165: 107.795 | D165: =Database!H166 -> #N/A
A166: Bhupali_8 | B166: 175.34 | C166: 98.7 | D166: =Database!H165 -> #N/A
A167: Bhupali_9 | B167: 240.895 | C167: 120.23 | D167: =Database!H167 -> #N/A
A168: Bhupali_10 | B168: 165.3 | C168: 156.05 | D168: =Database!H168 -> #N/A
A169: Bibhas_1 | B169: 293.06 | C169: 276.16 | D169: =Database!H169 -> #N/A
A170: Bibhas_2 | B170: 220.38 | C170: 92.95 | D170: =Database!H170 -> #N/A
A171: Bibhas_3 | B171: 245.32 | C171: 233.04 | D171: =Database!H171 -> #N/A
A172: Bibhas_4 | B172: 290.71 | C172: 117.13 | D172: =Database!H172 -> #N/A
A173: Bibhas_5 | B173: 243.215 | C173: 89.15 | D173: =Database!H173 -> #N/A
A174: Bibhas_6 | B174: 257.83 | C174: 104.35 | D174: =Database!H174 -> #N/A
A175: Bibhas_7 | B175: 201.85 | C175: 95.04 | D175: =Database!H175 -> #N/A
A176: Bibhas_8 | B176: 196.3 | C176: 100.39 | D176: =Database!H176 -> #N/A
A177: Bibhas_9 | B177: 261.34 | C177: 104.51 | D177: =Database!H177 -> #N/A
A178: Bihag_1 | B178: 218.3 | C178: 88.06 | D178: =Database!H178 -> #N/A
... A328: Devgiri Bilawal_10 | B328: 174.6 | C328: 138.75 | D328: =Database!H328 -> #N/A
A329: Dhanashree_1 | B329: 192.98 | C329: 79.38 | D329: =#REF! -> #REF!
A330: Dhanashree_2 | B330: 276.46 | C330: 220.06 | D330: =#REF! -> #REF!
A331: Dhani_1 | B331: 288.79 | C331: 233.01 | D331: =Database!H329 -> #N/A
A332: Dhani_2 | B332: 178.13 | C332: 86.665 | D332: =Database!H330 -> #N/A
A333: Dhani_3 | B333: 239.02 | C333: 105.17 | D333: =Database!H331 -> #N/A
A334: Dhani_4 | B334: 312.3 | C334: 90.88 | D334: =Database!H332 -> #N/A
A335: Dhani_5 | B335: 282.665 | C335: 96.81 | D335: =Database!H333 -> #N/A
A336: Dhani_6 | B336: 197.88 | C336: 96.865 | D336: =Database!H334 -> #N/A
A337: Dhani_7 | B337: 187.04 | C337: 104.85 | D337: =Database!H335 -> #N/A
A338: Dhani_8 | B338: 175 | C338: 72.72 | D338: =Database!H336 -> #N/A
A339: Dhani_9 | B339: 316.05 | C339: 117.48 | D339: =Database!H337 -> #N/A
...

Sheet Sheet12
B2: Total Records: 1098 Unique Ragas: 122 Unique Artists: 284
B3: Instrument | C3: Count
B4: Vocal | C4: 965
B5: Sitar | C5: 35
B6: Flute | C6: 35
B7: Sarod | C7: 21
B8: Sarangi | C8: 14
B10: Distribution of Gender
B11: Male performers significantly outnumber female performers in the dataset.
B12: Gender | C12: Count
B13: M | C13: 787
B14: F | C14: 311
B16: Distribution of Tonic
B22: Top 10 Artists by Count
B23: Artist | C23: Count
B24: Rashid Khan | C24: 72
B25: Ajoy Chakraborti | C25: 45
B26: Bhimsen Joshi | C26: 42
B27: Venkatesh Kumar | C27: 37
B28: Pt. Jasraj | C28: 34
B29: Kaushiki Chakraborti | C29: 31
B30: Kishori Amonkar | C30: 30
B31: Rajan Sajan Mishra | C31: 29
B32: Veena Sahasrabuddhe | C32: 26
B33: Manali Bose | C33: 26

Sheet Copy of Database
A1: Raga | B1: Tonic | C1: Filename | D1: Link | E1: Instrument | F1: Artist | G1: Start time | H1: Male/Female | I1: Channel | J1: Bandish | K1: End time | L1: Notes
A2: Abhogi | C2: =A2&"_"&COUNTIF($A$2:A2,A2) -> Abhogi_1 | E2: Vocal | F2: Bhimsen Joshi | I2: CompMusic DB
A3: Abhogi | C3: =A3&"_"&COUNTIF($A$2:A3,A3) -> Abhogi_2 | E3: Vocal | F3: Bhimsen Joshi | I3: CompMusic DB
A4: Abhogi | C4: =A4&"_"&COUNTIF($A$2:A4,A4) -> Abhogi_3 | E4: Vocal | F4: Bhimsen Joshi | I4: CompMusic DB
A5: Abhogi | C5: =A5&"_"&COUNTIF($A$2:A5,A5) -> Abhogi_4 | E5: Vocal | F5: Sanjeev Abhyankar | I5: CompMusic DB
A6: Abhogi | C6: =A6&"_"&COUNTIF($A$2:A6,A6) -> Abhogi_5 | E6: Vocal | F6: Jagdish Prasad | I6: CompMusic DB
A7: Abhogi | C7: =A7&"_"&COUNTIF($A$2:A7,A7) -> Abhogi_6 | E7: Vocal | F7: Anol Chatterjee | I7: CompMusic DB
A8: Abhogi | C8: =A8&"_"&COUNTIF($A$2:A8,A8) -> Abhogi_7 | E8: Vocal | F8: Rashid Khan | I8: CompMusic DB
A9: Abhogi | C9: =A9&"_"&COUNTIF($A$2:A9,A9) -> Abhogi_8 | E9: Vocal | F9: Salamat Ali Khan | I9: CompMusic DB
A10: Abhogi | C10: =A10&"_"&COUNTIF($A$2:A10,A10) -> Abhogi_9 | E10: Vocal | F10: Ajoy Chakraborti | I10: CompMusic DB
A11: Abhogi | C11: =A11&"_"&COUNTIF($A$2:A11,A11) -> Abhogi_10 | E11: Vocal | F11: Girija Devi | I11: CompMusic DB
A12: Adana | B12: C# | C12: =A12&"_"&COUNTIF($A$2:A12,A12) -> Adana_1 | D12: https://youtu.be/QXibHEHcwsc?si=sxmgmD3XRF27dPwB | E12: Vocal | F12: Ajoy Chakraborti | I12: Komal Nishad
A13: Adana | B13: D# | C13: =A13&"_"&COUNTIF($A$2:A13,A13) -> Adana_2 | D13: https://youtu.be/HyrXaj896jA?si=_z_Hbbdns67FtXyv | E13: Vocal | F13: Umrao Khan | I13: The Dream Journey
A14: Adana | B14: D# | C14: =A14&"_"&COUNTIF($A$2:A14,A14) -> Adana_3 | D14: https://youtu.be/yQfyusksjt4?si=oksGRG3MlcBQgqYN | E14: Vocal | F14: Jayateerth Mevundi | I14: Komal Nishad
A15: Adana | B15: C# | C15: =A15&"_"&COUNTIF($A$2:A15,A15) -> Adana_4 | D15: https://youtu.be/59fzA3Ipn-E?si=5onUBzyHCrs1EwOP | E15: Vocal | F15: Uday Bhawalkar
A16: Adana | B16: D# | C16: =A16&"_"&COUNTIF($A$2:A16,A16) -> Adana_5 | D16: https://youtu.be/Oi_6zNupJvk?si=GLKimNqBgC6NqVaa | E16: Vocal | F16: Venkatesh Kumar
A17: Adana | B17: C# | C17: =A17&"_"&COUNTIF($A$2:A17,A17) -> Adana_6 | D17: https://youtu.be/Hnw3BF08xSk?si=WKfZ_CIvRkC29Ij1 | E17: Vocal | F17: Ustad Salamat Ali & Ustad Nazakat Ali
A18: Adana | B18: C | C18: =A18&"_"&COUNTIF($A$2:A18,A18) -> Adana_7 | D18: https://youtu.be/1dTwD7dDzL4?si=4OA4jayRi8GqH7kp | E18: Vocal | F18: Pt. Jasraj
A19: Adana | B19: C# | C19: =A19&"_"&COUNTIF($A$2:A19,A19) -> Adana_8 | D19: https://youtu.be/7AYHKNG_qBo?si=BckiNEhrb8k-hRb3 | E19: Vocal | F19: Ajoy Chakraborti
A20: Adana | B20: F | C20: =A20&"_"&COUNTIF($A$2:A20,A20) -> Adana_9 | D20: https://youtu.be/RmBivLu-8HQ?si=odS481-bF8FvzzWI | E20: Vocal | F20: Aniruddh Aithal | L20: Recording is not great
A21: Adana | B21: B | C21: =A21&"_"&COUNTIF($A$2:A21,A21) -> Adana_10 | D21: https://www.youtube.com/watch?v=B4w6ZlhWVIs | E21: Vocal | F21: Veena Sahasrabuddhe
A22: Ahir Bhairav | C22: =A22&"_"&COUNTIF($A$2:A22,A22) -> Ahir Bhairav_1 | E22: Vocal | F22: Kaivalyakumar | I22: CompMusic DB
A23: Ahir Bhairav | C23: =A23&"_"&COUNTIF($A$2:A23,A23) -> Ahir Bhairav_2 | E23: Vocal | F23: Kumar Gandharv | I23: CompMusic DB
A24: Ahir Bhairav | C24: =A24&"_"&COUNTIF($A$2:A24,A24) -> Ahir Bhairav_3 | E24: Vocal | F24: Amir Khan | I24: CompMusic DB
A25: Ahir Bhairav | C25: =A25&"_"&COUNTIF($A$2:A25,A25) -> Ahir Bhairav_4 | E25: Vocal | F25: Pt. Jasraj | I25: CompMusic DB
A26: Ahir Bhairav | C26: =A26&"_"&COUNTIF($A$2:A26,A26) -> Ahir Bhairav_5 | E26: Vocal | F26: Pt. Jasraj | I26: CompMusic DB
A27: Ahir Bhairav | C27: =A27&"_"&COUNTIF($A$2:A27,A27) -> Ahir Bhairav_6 | E27: Vocal | F27: Rashid Khan | I27: CompMusic DB
A28: Ahir Bhairav | C28: =A28&"_"&COUNTIF($A$2:A28,A28) -> Ahir Bhairav_7 | E28: Vocal | F28: Kumar Gandharv | I28: CompMusic DB
A29: Ahir Bhairav | C29: =A29&"_"&COUNTIF($A$2:A29,A29) -> Ahir Bhairav_8 | E29: Vocal | F29: Omkar Dadarkar | I29: CompMusic DB
A30: Ahir Bhairav | C30: =A30&"_"&COUNTIF($A$2:A30,A30) -> Ahir Bhairav_9 | E30: Vocal | F30: Hirabai Barodekar | I30: CompMusic DB
A31: Ahir Bhairav | C31: =A31&"_"&COUNTIF($A$2:A31,A31) -> Ahir Bhairav_10 | E31: Vocal | F31: Ajoy Chakraborti | I31: CompMusic DB
A32: Alhaiya Bilawal | C32: =A32&"_"&COUNTIF($A$2:A32,A32) -> Alhaiya Bilawal_1 | E32: Vocal | F32: Dattatreya L Velankar | I32: CompMusic DB
A33: Alhaiya Bilawal | C33: =A33&"_"&COUNTIF($A$2:A33,A33) -> Alhaiya Bilawal_2 | E33: Vocal | F33: Dattatreya L Velankar | I33: CompMusic DB
... A41: Alhaiya Bilawal | C41: =A41&"_"&COUNTIF($A$2:A41,A41) -> Alhaiya Bilawal_10 | E41: Vocal | F41: Aslam Khan | I41: CompMusic DB
A42: Asavari (komal re) | B42: D# | C42: =A42&"_"&COUNTIF($A$2:A42,A42) -> Asavari (komal re)_1 | D42: https://youtu.be/QxuDG00m3-Y?si=0_Zgoy1s3GWoH2Ka | E42: Vocal | F42: Venkatesh Kumar | I42: First Edition Arts
A43: Asavari (komal re) | B43: D# | C43: =A43&"_"&COUNTIF($A$2:A43,A43) -> Asavari (komal re)_2 | D43: https://youtu.be/4lHpL82SM3g?si=jLhiatiJWRHKXrSi | E43: Vocal | F43: Omkar Dadarkar
A44: Asavari (komal re) | B44: D# | C44: =A44&"_"&COUNTIF($A$2:A44,A44) -> Asavari (komal re)_3 | D44: https://youtu.be/juftd3yg_wY?si=LrX1g7ur3pZOeox3 | E44: Vocal | F44: Ulhas Kashalkar
A45: Asavari (komal re) | B45: D#, E | C45: =A45&"_"&COUNTIF($A$2:A45,A45) -> Asavari (komal re)_4 | D45: https://youtu.be/s7WRnU0Fi0U?si=IC5cSqLJ9MFvF3zf | E45: Vocal | F45: Moinuddin and Nasir Aminuddin Dagar | L45: Some note between D# and E but not either of them
A46: Asavari (komal re) | B46: C | C46: =A46&"_"&COUNTIF($A$2:A46,A46) -> Asavari (komal re)_5 | D46: https://youtu.be/Z-SUL_6JiKs?si=EGl5zWM__bU5C9Kn | E46: Vocal | F46: Amir Khan
A47: Asavari (komal re) | B47: C# | C47: =A47&"_"&COUNTIF($A$2:A47,A47) -> Asavari (komal re)_6 | D47: https://youtu.be/lahaD7-B8DQ?si=-jxgx294FjSrNzjE | E47: Vocal | F47: Amir Khan
...

Sheet ArtistGender
A1: Artist | B1: Gender
A2: Aamir Sherazi | B2: M | D2: Tonic | E2: F | F2: M
A3: Aarti Anklikar Tikekar | B3: F | D3: A | E3: 35 | F3: 0
A4: Abby V | B4: M | D4: A | E4: 3 | F4: 0
A5: Abdul Rashid Khan | B5: M | D5: A# | E5: 91 | F5: 4
A6: Abhijith Shenoy | B6: M | D6: A#, B | E6: 1 | F6: 0
A7: Abhishek Borkar | B7: M | D7: A, A# | E7: 1 | F7: 0
A8: Abhishek Lahiri | B8: M | D8: B | E8: 23 | F8: 7
A9: Abhishek Raghuram | B9: M | D9: C | E9: 2 | F9: 19
A10: Aditya Madhavan | B10: M | D10: C | E10: 0 | F10: 1
A11: Aditya Modak | B11: M | D11: C# | E11: 14 | F11: 99
A12: Adnan Khan | B12: M | D12: C#, D | E12: 1 | F12: 7
A13: Ahsan Ali Khan | B13: M | D13: C, C# | E13: 1 | F13: 0
A14: Ajay Pohankar | B14: M | D14: D | E14: 11 | F14: 120
... A26: Anand Gopal | B26: M | D26: G, G# | E26: 0 | F26: 1
A27: Angad Gaikwad | B27: M
A28: Aniruddh Aithal | B28: M
A29: Anirudh Verma Collective | B29: M
A30: Annapurna Devi | B30: F
A31: Anol Chatterjee | B31: M
A32: Anupama Bhagwat | B32: F
A33: Anuradha Kuber | B33: F
A34: Apoorva Gokhale | B34: F
A35: Apoorva Gokhale, Pallavi Joshi | B35: F
A36: Arati Analikar, Devaki Pandit | B36: F
A37: Archana Kanhere | B37: F
A38: Armaan Khan | B38: M
A39: Artist
A40: Arun Dravid | B40: M
A41: Arun Kashalkar | B41: M
A42: Ashwini Bhide | B42: F
A43: Ashwini Gokhale | B43: F
A44: Ashwini Khaparde | B44: F
A45: Aslam Khan | B45: M
A46: Atri Kotal | B46: F
A47: Atul Nene | B47: M
A48: Azam Bai | B48: F
A49: Bade Ghulam Ali Khan | B49: M
A50: Bahauddin Dagar | B50: M
A51: Bai Azam Bai | B51: F
...

Sheet Bad Recordings

Sheet Non-Mainstream

Sheet MainLists
A1: Artist | B1: Instrument | C1: Raga | D1: Tonics
A2: Rashid Khan | B2: Vocal | C2: Abhogi | D2: C
A3: Venkatesh Kumar | B3: Sitar | C3: Adana | D3: C#
A4: Bhimsen Joshi | B4: Flute | C4: Ahir Bhairav | D4: D
A5: Manali Bose | B5: Sarod | C5: Alhaiya Bilawal | D5: D#
A6: Rajan Sajan Mishra | B6: Sarangi | C6: Asavari (komal re) | D6: E
A7: Ashwini Bhide | B7: Violin | C7: Bageshri | D7: F
A8: Ajoy Chakraborti | B8: Rudra Veena | C8: Bahar | D8: F#
A9: Ulhas Kashalkar | B9: Shehnai | C9: Bairagi | D9: G
A10: Kishori Amonkar | B10: Surbahar | C10: Bairagi Todi | D10: G#
A11: Hariprasad Chaurasia | B11: Santoor | C11: Basant | D11: A
A12: Kaushiki Chakraborti | B12: Mohan Veena | C12: Basant Mukhari | D12: A#
A13: Mallikarjun Mansur | B13: Shehenai | C13: Bhairav | D13: B
A14: Shashank Subramanyam | B14: Mandolin | C14: Bhairavi
A15: D V Paluskar | B15: Multiple | C15: Bhatiyar
A16: Shahid Parvez | B16: Esraj | C16: Bheem
A17: Veena Sahasrabuddhe | B17: Jal Tarang | C17: Bhimpalasi
A18: Amir Khan | C18: Bhupali Todi
A19: Apoorva Gokhale | C19: Bhupali
A20: Sanjeev Abhyankar | C20: Bibhas
A21: Prabha Atre | C21: Bihag
A22: Moumita Mitra | C22: Bihagda
A23: Jitendra Abhisheki | C23: Bihari
A24: Bade Ghulam Ali Khan | C24: Bilaskhani Todi
A25: Shruti Sadolikar | C25: Bilawal
A26: Sawani Shende | C26: Champakali
A27: Uday Bhawalkar | C27: Chandrakauns
A28: Kumar Gandharv | C28: Chandranandan
A29: Roopa Panesar | C29: Charukeshi
... A97: Rewa Natu | C97: Puriya Kalyan
A98: Ramashreya Jha
A99: Ranjani and Gayatri | C99: Rageshri
A100: Rattan Mohan Sharma | C100: Ramdasi Malhar
A101: Vijaya Jadhav Gatlewal | C101: Ramkali
A102: Sudhree Jyostsana Keshav Bhole | C102: Salagavarali
A103: Vinayak Torvi | C103: Sarang
A104: Poornima Kulkarni | C104: Saraswati
A105: Zohrabai Agrewali | C105: Shahana
A106: Zohaib Ali | C106: Shankara
A107: Pramod Deshmukh | C107: Shivranjani
...

Sheet RagaCount
A1: =IFERROR(__xludf.DUMMYFUNCTION("QUERY(Database!A:A, ""SELECT A, COUNT(A) GROUP BY A ORDER BY COUNT(A) LABEL COUNT(A) 'Frequency'"") "),"") | B1: =IFERROR(__xludf.DUMMYFUNCTION("""COMPUTED_VALUE"""),"Frequency") -> Frequency
A2: =IFERROR(__xludf.DUMMYFUNCTION("""COMPUTED_VALUE"""),"Jaldhar Basanti") -> Jaldhar Basanti | B2: =IFERROR(__xludf.DUMMYFUNCTION("""COMPUTED_VALUE"""),1.0) -> 1
A3: =IFERROR(__xludf.DUMMYFUNCTION("""COMPUTED_VALUE"""),"Raga") -> Raga | B3: =IFERROR(__xludf.DUMMYFUNCTION("""COMPUTED_VALUE"""),1.0) -> 1
A4: =IFERROR(__xludf.DUMMYFUNCTION("""COMPUTED_VALUE"""),"Zila Kafi") -> Zila Kafi | B4: =IFERROR(__xludf.DUMMYFUNCTION("""COMPUTED_VALUE"""),1.0) -> 1
A5: =IFERROR(__xludf.DUMMYFUNCTION("""COMPUTED_VALUE"""),"Bheem") -> Bheem | B5: =IFERROR(__xludf.DUMMYFUNCTION("""COMPUTED_VALUE"""),3.0) -> 3
A6: =IFERROR(__xludf.DUMMYFUNCTION("""COMPUTED_VALUE"""),"Hemshri") -> Hemshri | B6: =IFERROR(__xludf.DUMMYFUNCTION("""COMPUTED_VALUE"""),3.0) -> 3
A7: =IFERROR(__xludf.DUMMYFUNCTION("""COMPUTED_VALUE"""),"Tilang Bahar") -> Tilang Bahar | B7: =IFERROR(__xludf.DUMMYFUNCTION("""COMPUTED_VALUE"""),4.0) -> 4
A8: =IFERROR(__xludf.DUMMYFUNCTION("""COMPUTED_VALUE"""),"Hem Bihag") -> Hem Bihag | B8: =IFERROR(__xludf.DUMMYFUNCTION("""COMPUTED_VALUE"""),5.0) -> 5
A9: =IFERROR(__xludf.DUMMYFUNCTION("""COMPUTED_VALUE"""),"Bilawal") -> Bilawal | B9: =IFERROR(__xludf.DUMMYFUNCTION("""COMPUTED_VALUE"""),6.0) -> 6
A10: =IFERROR(__xludf.DUMMYFUNCTION("""COMPUTED_VALUE"""),"Chandranandan") -> Chandranandan | B10: =IFERROR(__xludf.DUMMYFUNCTION("""COMPUTED_VALUE"""),6.0) -> 6
A11: =IFERROR(__xludf.DUMMYFUNCTION("""COMPUTED_VALUE"""),"Gopika Basant") -> Gopika Basant | B11: =IFERROR(__xludf.DUMMYFUNCTION("""COMPUTED_VALUE"""),6.0) -> 6
A12: =IFERROR(__xludf.DUMMYFUNCTION("""COMPUTED_VALUE"""),"Hari Kauns") -> Hari Kauns | B12: =IFERROR(__xludf.DUMMYFUNCTION("""COMPUTED_VALUE"""),6.0) -> 6
A13: =IFERROR(__xludf.DUMMYFUNCTION("""COMPUTED_VALUE"""),"Megh Malhar") -> Megh Malhar | B13: =IFERROR(__xludf.DUMMYFUNCTION("""COMPUTED_VALUE"""),6.0) -> 6
A14: =IFERROR(__xludf.DUMMYFUNCTION("""COMPUTED_VALUE"""),"Shivranjani") -> Shivranjani | B14: =IFERROR(__xludf.DUMMYFUNCTION("""COMPUTED_VALUE"""),6.0) -> 6
A15: =IFERROR(__xludf.DUMMYFUNCTION("""COMPUTED_VALUE"""),"Bairagi Todi") -> Bairagi Todi | B15: =IFERROR(__xludf.DUMMYFUNCTION("""COMPUTED_VALUE"""),7.0) -> 7
A16: =IFERROR(__xludf.DUMMYFUNCTION("""COMPUTED_VALUE"""),"Jaldhar Kedar") -> Jaldhar Kedar | B16: =IFERROR(__xludf.DUMMYFUNCTION("""COMPUTED_VALUE"""),7.0) -> 7
A17: =IFERROR(__xludf.DUMMYFUNCTION("""COMPUTED_VALUE"""),"Jayat") -> Jayat | B17: =IFERROR(__xludf.DUMMYFUNCTION("""COMPUTED_VALUE"""),7.0) -> 7
A18: =IFERROR(__xludf.DUMMYFUNCTION("""COMPUTED_VALUE"""),"Pilu") -> Pilu | B18: =IFERROR(__xludf.DUMMYFUNCTION("""COMPUTED_VALUE"""),7.0) -> 7
A19: =IFERROR(__xludf.DUMMYFUNCTION("""COMPUTED_VALUE"""),"Shobhawari") -> Shobhawari | B19: =IFERROR(__xludf.DUMMYFUNCTION("""COMPUTED_VALUE"""),7.0) -> 7
A20: =IFERROR(__xludf.DUMMYFUNCTION("""COMPUTED_VALUE"""),"Bihari") -> Bihari | B20: =IFERROR(__xludf.DUMMYFUNCTION("""COMPUTED_VALUE"""),8.0) -> 8
A21: =IFERROR(__xludf.DUMMYFUNCTION("""COMPUTED_VALUE"""),"Hanskinki") -> Hanskinki | B21: =IFERROR(__xludf.DUMMYFUNCTION("""COMPUTED_VALUE"""),8.0) -> 8
A22: =IFERROR(__xludf.DUMMYFUNCTION("""COMPUTED_VALUE"""),"Khambhavati") -> Khambhavati | B22: =IFERROR(__xludf.DUMMYFUNCTION("""COMPUTED_VALUE"""),8.0) -> 8
A23: =IFERROR(__xludf.DUMMYFUNCTION("""COMPUTED_VALUE"""),"Narayani") -> Narayani | B23: =IFERROR(__xludf.DUMMYFUNCTION("""COMPUTED_VALUE"""),8.0) -> 8
A24: =IFERROR(__xludf.DUMMYFUNCTION("""COMPUTED_VALUE"""),"Parameshwari") -> Parameshwari | B24: =IFERROR(__xludf.DUMMYFUNCTION("""COMPUTED_VALUE"""),8.0) -> 8
A25: =IFERROR(__xludf.DUMMYFUNCTION("""COMPUTED_VALUE"""),"Shahana") -> Shahana | B25: =IFERROR(__xludf.DUMMYFUNCTION("""COMPUTED_VALUE"""),8.0) -> 8
A26: =IFERROR(__xludf.DUMMYFUNCTION("""COMPUTED_VALUE"""),"Tilak Kamod") -> Tilak Kamod | B26: =IFERROR(__xludf.DUMMYFUNCTION("""COMPUTED_VALUE"""),8.0) -> 8
A27: =IFERROR(__xludf.DUMMYFUNCTION("""COMPUTED_VALUE"""),"Basant Mukhari") -> Basant Mukhari | B27: =IFERROR(__xludf.DUMMYFUNCTION("""COMPUTED_VALUE"""),9.0) -> 9
A28: =IFERROR(__xludf.DUMMYFUNCTION("""COMPUTED_VALUE"""),"Bhimpalasi") -> Bhimpalasi | B28: =IFERROR(__xludf.DUMMYFUNCTION("""COMPUTED_VALUE"""),9.0) -> 9
A29: =IFERROR(__xludf.DUMMYFUNCTION("""COMPUTED_VALUE"""),"Bhupali Todi") -> Bhupali Todi | B29: =IFERROR(__xludf.DUMMYFUNCTION("""COMPUTED_VALUE"""),9.0) -> 9
A30: =IFERROR(__xludf.DUMMYFUNCTION("""COMPUTED_VALUE"""),"Bibhas") -> Bibhas | B30: =IFERROR(__xludf.DUMMYFUNCTION("""COMPUTED_VALUE"""),9.0) -> 9
A31: =IFERROR(__xludf.DUMMYFUNCTION("""COMPUTED_VALUE"""),"Bihagda") -> Bihagda | B31: =IFERROR(__xludf.DUMMYFUNCTION("""COMPUTED_VALUE"""),9.0) -> 9
A32: =IFERROR(__xludf.DUMMYFUNCTION("""COMPUTED_VALUE"""),"Chhayanat") -> Chhayanat | B32: =IFERROR(__xludf.DUMMYFUNCTION("""COMPUTED_VALUE"""),9.0) -> 9
A33: =IFERROR(__xludf.DUMMYFUNCTION("""COMPUTED_VALUE"""),"Desi") -> Desi | B33: =IFERROR(__xludf.DUMMYFUNCTION("""COMPUTED_VALUE"""),9.0) -> 9
A34: =IFERROR(__xludf.DUMMYFUNCTION("""COMPUTED_VALUE"""),"Dev Gandhar") -> Dev Gandhar | B34: =IFERROR(__xludf.DUMMYFUNCTION("""COMPUTED_VALUE"""),9.0) -> 9
A35: =IFERROR(__xludf.DUMMYFUNCTION("""COMPUTED_VALUE"""),"Dhani") -> Dhani | B35: =IFERROR(__xludf.DUMMYFUNCTION("""COMPUTED_VALUE"""),9.0) -> 9
A36: =IFERROR(__xludf.DUMMYFUNCTION("""COMPUTED_VALUE"""),"Gauri") -> Gauri | B36: =IFERROR(__xludf.DUMMYFUNCTION("""COMPUTED_VALUE"""),9.0) -> 9
A37: =IFERROR(__xludf.DUMMYFUNCTION("""COMPUTED_VALUE"""),"Gorakh Kalyan") -> Gorakh Kalyan | B37: =IFERROR(__xludf.DUMMYFUNCTION("""COMPUTED_VALUE"""),9.0) -> 9
A38: =IFERROR(__xludf.DUMMYFUNCTION("""COMPUTED_VALUE"""),"Gurjari Todi") -> Gurjari Todi | B38: =IFERROR(__xludf.DUMMYFUNCTION("""COMPUTED_VALUE"""),9.0) -> 9
A39: =IFERROR(__xludf.DUMMYFUNCTION("""COMPUTED_VALUE"""),"Hindol") -> Hindol | B39: =IFERROR(__xludf.DUMMYFUNCTION("""COMPUTED_VALUE"""),9.0) -> 9
A40: =IFERROR(__xludf.DUMMYFUNCTION("""COMPUTED_VALUE"""),"Jaunpuri") -> Jaunpuri | B40: =IFERROR(__xludf.DUMMYFUNCTION("""COMPUTED_VALUE"""),9.0) -> 9
...

Sheet InstrumentCount
A1: =IFERROR(__xludf.DUMMYFUNCTION("QUERY(Database!E:E, ""SELECT F, COUNT(F) GROUP BY F LABEL COUNT(F) 'Frequency'"")"),"#VALUE!") -> #VALUE!

Sheet ArtistCount
A1: =IFERROR(__xludf.DUMMYFUNCTION("QUERY(Database!F:F, ""SELECT G, COUNT(G) GROUP BY G LABEL COUNT(G) 'Frequency'"")"),"#VALUE!") -> #VALUE! | C1: Gender
C2: M
C3: F
C4: M
C5: M
C6: M
C7: M
C8: M
C9: M
C10: M
C11: M
C12: M
C13: M
... C286: M

Sheet Chart1 Frequency of Each Tonic 
A3: Tonic | B3: F | C3: M
A4: A | B4: 35
A5: A | B5: 3
A6: A# | B6: 91 | C6: 2
A7: A#, B | B7: 1
A8: A, A# | B8: 1
A9: B | B9: 23 | C9: 2
A10: C | B10: 2 | C10: 8
A11: C | C11: 1
A12: C# | B12: 8 | C12: 86
A13: C#, D | B13: 1 | C13: 3
A14: C, C# | B14: 1
A15: D | B15: 4 | C15: 96
A16: D | C16: 1
A17: D# | B17: 4 | C17: 134
A18: D# | C18: 1
A19: D#, E | C19: 2
A20: D, D# | C20: 3
A21: E | B21: 1 | C21: 36
A22: F | B22: 1 | C22: 11
A23: F# | C23: 12
A24: G | B24: 4 | C24: 1
A25: G# | B25: 31 | C25: 3

Sheet Chart1 Distribution of Median P
A3: vocals | B3: vocals
A4: 261.45 | B4: 261.45
A5: 362.88 | B5: 362.88
A6: 304.12 | B6: 304.12
A7: 232.61 | B7: 232.61
A8: 311.42 | B8: 311.42
A9: 261.33 | B9: 261.33
A10: 246.86 | B10: 246.86
A11: 246.36 | B11: 246.36
A12: 283.47 | B12: 283.47
A13: 147.38 | B13: 147.38
A14: 142 | B14: 142
A15: 159.07 | B15: 159.07
... A311: 192.53 | B311: 192.53

Sheet Sheet13
A1: The descriptive statistics and histograms of median pitch (vocals) for males and females show distinct distributions, allowing for the identification of a threshold to classify median pitch as male or female. Key Takeaways: • Distinct Pitch Ranges: Males generally have lower median pitches, while females generally have higher median pitches. • The mean median pitch for males is approximately 226.56 Hz, with a standard deviation of 68.21 Hz. • The mean median pitch for females is approximately 268.92 Hz, with a standard deviation of 67.62 Hz. • The median pitch for males ranges from 111.19 Hz to 582.62 Hz. • The median pitch for females ranges from 136.06 Hz to 550.21 Hz. • Overlap in Distributions: While there are clear differences, there's an overlap in the median pitch ranges, particularly between approximately 150 Hz and 350 Hz. • The 75th percentile for males is 260.44 Hz, indicating that 75% of male median pitches are below this value. • The 25th percentile for females is 228.33 Hz, indicating that 25% of female median pitches are below this value. Proposed Threshold: Based on the analysis, a reasonable threshold to classify median pitch as male or female could be around 250 Hz. • Median pitches below 250 Hz would likely be classified as male. • Median pitches above 250 Hz would likely be classified as female. This threshold is chosen because it falls within the overlapping region but leans towards separating the bulk of the male distribution from the female distribution, as shown in the histograms. It is important to note that due to the overlap, there will be some misclassifications, especially for individuals whose median pitch falls within the overlapping range. Visualizations: • Distribution of Median Pitch for Males: This chart shows the frequency of different median pitch values for males. • Distribution of Median Pitch for Females: This chart shows the frequency of different median pitch values for females. | F1: The descriptive statistics and histograms of median pitch (vocals) for males and females show distinct distributions, allowing for the identification of a threshold to classify median pitch as male or female. Key Takeaways: • Distinct Pitch Ranges: Males generally have lower median pitches, while females generally have higher median pitches. • The mean median pitch for males is approximately 226.56 Hz, with a standard deviation of 68.21 Hz. • The mean median pitch for females is approximately 268.92 Hz, with a standard deviation of 67.62 Hz. • The median pitch for males ranges from 111.19 Hz to 582.62 Hz. • The median pitch for females ranges from 136.06 Hz to 550.21 Hz. • Overlap in Distributions: While there are clear differences, there's an overlap in the median pitch ranges, particularly between approximately 150 Hz and 350 Hz. • The 75th percentile for males is 260.44 Hz, indicating that 75% of male median pitches are below this value. • The 25th percentile for females is 228.33 Hz, indicating that 25% of female median pitches are below this value. Proposed Threshold: Based on the analysis, a reasonable threshold to classify median pitch as male or female could be around 250 Hz. • Median pitches below 250 Hz would likely be classified as male. • Median pitches above 250 Hz would likely be classified as female. This threshold is chosen because it falls within the overlapping region but leans towards separating the bulk of the male distribution from the female distribution, as shown in the histograms. It is important to note that due to the overlap, there will be some misclassifications, especially for individuals whose median pitch falls within the overlapping range. Visualizations: • Distribution of Median Pitch for Males: This chart shows the frequency of different median pitch values for males. • Distribution of Median Pitch for Females: This chart shows the frequency of different median pitch values for females.
A3: vocals | B3: vocals
A4: 175.435 | B4: 175.435
A5: 171.375 | B5: 171.375
A6: 185.33 | B6: 185.33
A7: 247.93 | B7: 247.93
A8: 159.13 | B8: 159.13
A9: 168.45 | B9: 168.45
A10: 174.92 | B10: 174.92
A11: 157.98 | B11: 157.98
A12: 147.37 | B12: 147.37
A13: 253.34 | B13: 253.34
A14: 277.03 | B14: 277.03
A15: 235.86 | B15: 235.86
... A782: 293.03 | B782: 293.03
